File: herald_visualization/XRD Plotting Scripts (Riley)/Calculated_Profile_Fe0p56Mn0p44F3_60to25wt_SuperP_100min_20-70deg.XRDML
<?xml version="1.0" encoding="UTF-8"?>
<xrdMeasurements xmlns="http://www.xrdml.com/XRDMeasurement/1.5" xmlns:xsi="http://www.w3.org/2001/XMLSchema-instance" xsi:schemaLocation="http://www.xrdml.com/XRDMeasurement/1.5 http://www.xrdml.com/XRDMeasurement/1.5/XRDMeasurement.xsd" status="Completed">
	<comment>
		<entry>Configuration=OEC Motorized Platform, Owner=yansari, Creation date=2/26/2007 1:45:53 PM</entry>
		<entry>Goniometer=PW3050/60 (Theta/Theta); Minimum step size 2Theta:0.001; Minimum step size Omega:0.001</entry>
		<entry>Sample stage=Open Eulerian Cradle (manual Z); Minimum step size Phi:0.01; Minimum step size Chi:0.01</entry>
		<entry>Diffractometer system=XPERT-PRO</entry>
		<entry>Measurement program=C:\PANalytical\Data Collector\Programs\eschlerc\PROPEL-1K\20-70deg_40min_mechanochemical_synth_char.xrdmp, Identifier={7F0145CF-481E-4DB5-821B-12BCA6FF3B92}</entry>
		<entry>20-70deg, 40min for mechanochemical synthesis characterization</entry>
		<entry>PHD Lower Level = 6.20 (keV), PHD Upper Level = 16.10 (keV)</entry>
	</comment>
	<xrdMeasurement sampleMode="Reflection" measurementType="Scan" status="Completed">
		<usedWavelength intended="K-Alpha 1">
			<kAlpha1 unit="Angstrom">1.540598</kAlpha1>
			<kAlpha2 unit="Angstrom">1.544426</kAlpha2>
			<kBeta unit="Angstrom">1.392250</kBeta>
			<ratioKAlpha2KAlpha1>0.500000</ratioKAlpha2KAlpha1>
		</usedWavelength>
		<incidentBeamPath>
			<radius unit="mm">240.000</radius>
			<xRayTube>
				<tension unit="kV">45</tension>
				<current unit="mA">40</current>
				<anodeMaterial>Cu</anodeMaterial>
			</xRayTube>
			<divergenceSlit xsi:type="fixedDivergenceSlitType">
				<angle unit="deg">0.500</angle>
			</divergenceSlit>
		</incidentBeamPath>
		<diffractedBeamPath>
			<radius unit="mm">240.000</radius>
			<receivingSlit>
				<height unit="mm">0.100</height>
			</receivingSlit>
		</diffractedBeamPath>
		<scan appendNumber="0" scanAxis="Gonio" mode="Continuous" status="Completed">
			<header>
				<startTimeStamp>2025-02-14T14:48:41--05:00</startTimeStamp>
				<author>
					<name>XRAY03</name>
				</author>
				<source>
					<applicationSoftware version="5.1.0">HighScore Plus</applicationSoftware>
				</source>
			</header>
			<dataPoints>
				<positions axis="2Theta" unit="deg">
					<startPosition>20.00835563</startPosition>
					<endPosition>69.98835563</endPosition>
				</positions>
				<commonCountingTime unit="seconds">99.695</commonCountingTime>
				<intensities unit="counts">6936 6932 6927 6923 6919 6915 6910 6906 6902 6897 6893 6889 6885 6880 6876 6872 6868 6864 6859 6855 6851 6847 6843 6839 6835 6830 6826 6822 6818 6814 6810 6806 6802 6798 6794 6790 6786 6782 6778 6774 6770 6766 6762 6758 6754 6750 6746 6742 6739 6735 6731 6727 6723 6719 6716 6712 6708 6704 6700 6697 6693 6689 6686 6682 6678 6675 6671 6667 6664 6660 6656 6653 6649 6646 6642 6639 6635 6632 6628 6625 6621 6618 6614 6611 6608 6604 6601 6598 6594 6591 6588 6585 6581 6578 6575 6572 6569 6566 6563 6560 6557 6554 6551 6548 6545 6542 6539 6536 6534 6531 6528 6525 6523 6520 6518 6515 6513 6510 6508 6506 6503 6501 6499 6497 6495 6493 6491 6489 6487 6486 6484 6483 6481 6480 6479 6478 6477 6476 6476 6475 6475 6475 6476 6476 6477 6478 6480 6482 6484 6486 6489 6493 6496 6501 6505 6510 6515 6521 6527 6533 6540 6547 6554 6561 6569 6577 6585 6593 6602 6612 6622 6634 6647 6662 6679 6699 6722 6748 6778 6812 6851 6895 6945 7000 7062 7131 7207 7291 7382 7481 7588 7703 7826 7956 8093 8237 8386 8540 8698 8857 9018 9176 9331 9479 9617 9744 9855 9948 10020 10069 10094 10097 10077 10036 9976 9897 9803 9695 9575 9445 9308 9165 9018 8869 8720 8572 8425 8282 8142 8006 7876 7751 7631 7518 7411 7310 7215 7126 7043 6966 6895 6829 6768 6712 6660 6613 6569 6530 6493 6460 6430 6402 6376 6353 6331 6311 6293 6276 6260 6245 6231 6218 6206 6195 6184 6173 6164 6154 6145 6136 6128 6120 6112 6105 6097 6090 6083 6077 6070 6064 6058 6052 6046 6040 6034 6029 6023 6018 6012 6007 6002 5997 5992 5987 5983 5978 5973 5969 5964 5960 5956 5951 5947 5943 5939 5935 5931 5927 5923 5919 5915 5911 5908 5904 5900 5897 5893 5889 5886 5882 5879 5875 5872 5868 5865 5862 5858 5855 5852 5848 5845 5842 5839 5836 5832 5829 5826 5823 5820 5817 5814 5811 5808 5805 5802 5799 5796 5793 5790 5787 5784 5782 5779 5776 5773 5770 5767 5765 5762 5759 5756 5754 5751 5748 5745 5743 5740 5737 5735 5732 5729 5727 5724 5722 5719 5716 5714 5711 5709 5706 5704 5701 5699 5696 5694 5691 5689 5686 5684 5681 5679 5676 5674 5671 5669 5667 5664 5662 5659 5657 5655 5653 5650 5648 5646 5643 5641 5639 5636 5634 5632 5630 5627 5625 5623 5620 5618 5616 5614 5611 5609 5607 5605 5603 5600 5598 5596 5594 5592 5589 5587 5585 5583 5581 5579 5576 5574 5572 5570 5568 5566 5564 5562 5560 5558 5555 5553 5551 5549 5547 5545 5543 5541 5539 5537 5535 5533 5532 5530 5528 5526 5524 5522 5520 5518 5516 5514 5512 5510 5508 5507 5505 5503 5501 5499 5497 5496 5494 5492 5490 5489 5487 5485 5483 5482 5480 5478 5477 5475 5474 5472 5471 5469 5468 5467 5466 5464 5463 5462 5462 5461 5461 5460 5460 5460 5461 5462 5463 5464 5466 5468 5471 5474 5478 5482 5486 5491 5496 5502 5507 5513 5519 5525 5531 5536 5541 5544 5547 5549 5549 5548 5545 5541 5536 5530 5523 5515 5506 5497 5488 5479 5470 5461 5452 5443 5435 5427 5420 5413 5406 5400 5394 5389 5384 5380 5375 5372 5368 5365 5361 5358 5356 5353 5350 5348 5346 5340 5338 5336 5334 5330 5329 5327 5325 5323 5321 5319 5318 5316 5314 5313 5311 5309 5308 5306 5304 5303 5301 5300 5298 5296 5295 5293 5292 5290 5289 5287 5286 5284 5283 5281 5280 5278 5277 5275 5274 5273 5271 5270 5268 5267 5265 5264 5263 5261 5260 5259 5257 5256 5254 5253 5252 5250 5249 5248 5246 5245 5244 5242 5241 5240 5239 5237 5236 5235 5233 5232 5231 5230 5228 5227 5226 5225 5223 5222 5221 5220 5219 5218 5216 5215 5214 5213 5212 5211 5210 5209 5208 5207 5206 5205 5204 5203 5202 5201 5200 5199 5198 5197 5196 5195 5194 5193 5192 5191 5190 5189 5188 5187 5186 5185 5183 5182 5181 5180 5179 5178 5177 5176 5175 5174 5173 5172 5171 5170 5169 5168 5167 5166 5165 5165 5164 5163 5162 5162 5161 5160 5160 5159 5158 5158 5157 5157 5156 5156 5156 5155 5155 5155 5154 5154 5154 5154 5154 5154 5155 5155 5156 5156 5157 5158 5159 5160 5162 5164 5166 5168 5171 5174 5177 5181 5185 5190 5195 5201 5207 5214 5222 5230 5239 5249 5259 5270 5282 5294 5307 5320 5334 5349 5364 5380 5396 5412 5428 5444 5460 5475 5490 5505 5518 5530 5540 5549 5556 5562 5565 5566 5566 5563 5559 5554 5546 5538 5528 5517 5506 5493 5480 5467 5453 5440 5426 5412 5398 5385 5372 5359 5347 5336 5325 5315 5306 5297 5289 5282 5276 5270 5266 5262 5259 5257 5255 5254 5254 5255 5257 5259 5261 5264 5268 5272 5276 5280 5284 5288 5293 5296 5300 5303 5305 5306 5307 5307 5306 5304 5301 5297 5293 5288 5282 5276 5269 5262 5254 5246 5238 5229 5221 5212 5203 5195 5186 5177 5169 5161 5153 5145 5137 5130 5123 5116 5109 5103 5097 5091 5085 5080 5075 5070 5066 5061 5057 5053 5050 5046 5043 5040 5037 5034 5032 5029 5027 5025 5023 5021 5019 5017 5015 5014 5012 5011 5009 5008 5007 5005 5004 5003 5002 5001 5000 4999 4998 4998 4997 4996 4995 4995 4994 4994 4993 4993 4992 4992 4992 4991 4991 4991 4990 4990 4989 4989 4988 4987 4986 4986 4985 4984 4983 4982 4980 4979 4978 4977 4976 4974 4973 4972 4971 4970 4969 4968 4967 4966 4965 4964 4963 4962 4961 4961 4960 4959 4958 4958 4957 4956 4956 4955 4955 4954 4953 4953 4952 4952 4951 4950 4950 4949 4949 4948 4948 4947 4947 4946 4945 4945 4944 4944 4943 4943 4942 4942 4941 4941 4940 4940 4939 4939 4939 4938 4938 4937 4937 4936 4936 4935 4935 4935 4934 4934 4933 4933 4932 4932 4932 4931 4931 4930 4930 4930 4929 4929 4928 4928 4928 4927 4927 4927 4926 4926 4925 4925 4925 4924 4924 4924 4923 4923 4923 4923 4922 4922 4922 4921 4921 4921 4920 4920 4920 4920 4919 4919 4919 4919 4918 4918 4918 4918 4918 4918 4917 4917 4917 4917 4917 4917 4917 4917 4918 4918 4918 4918 4918 4919 4919 4920 4920 4920 4921 4921 4922 4922 4923 4923 4924 4924 4924 4924 4924 4924 4924 4923 4923 4923 4922 4921 4921 4920 4920 4919 4919 4918 4918 4917 4917 4916 4916 4916 4916 4916 4916 4916 4916 4916 4917 4917 4918 4918 4919 4920 4921 4922 4923 4924 4926 4927 4929 4930 4932 4934 4937 4939 4941 4944 4946 4949 4952 4955 4958 4961 4964 4968 4971 4975 4979 4983 4988 4993 4998 5004 5010 5016 5023 5030 5038 5046 5055 5064 5074 5083 5094 5104 5115 5126 5137 5148 5159 5171 5181 5192 5202 5212 5221 5229 5236 5242 5248 5251 5254 5256 5256 5256 5254 5252 5248 5243 5238 5231 5224 5217 5209 5200 5191 5182 5172 5163 5153 5143 5133 5123 5113 5103 5094 5084 5075 5066 5057 5049 5040 5032 5024 5017 5010 5003 4996 4990 4983 4978 4972 4967 4962 4957 4953 4949 4945 4941 4938 4935 4932 4929 4926 4924 4922 4920 4918 4916 4914 4912 4911 4910 4908 4907 4906 4905 4904 4903 4903 4902 4901 4901 4900 4900 4900 4899 4899 4899 4899 4899 4900 4900 4900 4901 4902 4902 4903 4904 4905 4907 4908 4910 4912 4913 4915 4917 4919 4921 4923 4925 4927 4929 4931 4932 4933 4934 4935 4936 4937 4937 4938 4938 4938 4938 4938 4938 4938 4938 4938 4938 4938 4938 4938 4937 4937 4937 4937 4936 4936 4935 4934 4934 4933 4932 4931 4930 4929 4927 4926 4925 4923 4922 4921 4919 4918 4916 4915 4913 4912 4911 4909 4908 4907 4905 4904 4903 4902 4901 4900 4900 4899 4898 4898 4897 4897 4897 4896 4896 4896 4896 4896 4896 4896 4896 4896 4896 4895 4895 4895 4894 4894 4893 4893 4892 4891 4890 4889 4888 4887 4887 4886 4885 4884 4883 4882 4882 4881 4880 4880 4879 4879 4878 4878 4878 4877 4877 4877 4876 4876 4876 4876 4876 4876 4876 4875 4875 4875 4875 4875 4875 4875 4875 4875 4875 4875 4875 4875 4875 4875 4875 4875 4875 4875 4875 4875 4875 4874 4874 4874 4875 4875 4875 4875 4875 4875 4875 4875 4875 4875 4875 4875 4875 4875 4875 4875 4875 4875 4875 4875 4875 4875 4875 4875 4875 4875 4875 4875 4875 4875 4875 4875 4876 4876 4876 4876 4876 4876 4876 4876 4876 4876 4876 4876 4876 4876 4876 4876 4876 4877 4877 4877 4877 4877 4877 4877 4878 4878 4878 4878 4878 4878 4878 4878 4878 4879 4879 4879 4879 4879 4879 4879 4879 4879 4879 4879 4880 4880 4880 4880 4880 4880 4880 4880 4880 4881 4881 4881 4881 4881 4881 4881 4881 4882 4882 4882 4882 4882 4882 4882 4882 4883 4883 4883 4883 4883 4883 4883 4884 4884 4884 4884 4884 4884 4884 4885 4885 4885 4885 4885 4886 4886 4886 4886 4886 4887 4887 4887 4887 4888 4888 4888 4888 4888 4889 4889 4889 4889 4890 4890 4890 4890 4891 4891 4891 4891 4892 4892 4893 4893 4893 4894 4894 4895 4895 4896 4896 4897 4897 4898 4899 4899 4900 4901 4902 4902 4903 4904 4905 4905 4906 4907 4907 4908 4908 4909 4909 4909 4910 4910 4910 4910 4911 4911 4911 4911 4911 4911 4912 4912 4912 4912 4913 4913 4914 4914 4915 4915 4916 4917 4918 4919 4920 4921 4922 4923 4925 4926 4928 4929 4931 4933 4935 4937 4940 4942 4945 4948 4951 4954 4958 4962 4966 4970 4975 4980 4985 4991 4997 5003 5010 5017 5025 5033 5042 5051 5060 5070 5080 5091 5103 5114 5127 5140 5153 5167 5181 5195 5210 5225 5240 5256 5271 5287 5303 5318 5333 5347 5362 5375 5387 5399 5409 5418 5426 5432 5436 5439 5441 5442 5441 5438 5435 5430 5425 5418 5410 5402 5392 5383 5372 5361 5350 5339 5327 5315 5303 5290 5278 5266 5253 5241 5229 5217 5205 5193 5182 5171 5160 5149 5139 5128 5118 5109 5100 5091 5082 5074 5066 5058 5050 5043 5036 5030 5024 5018 5012 5007 5002 4997 4992 4988 4984 4980 4977 4973 4970 4967 4964 4962 4959 4957 4955 4953 4951 4949 4947 4946 4945 4943 4942 4941 4940 4939 4939 4938 4937 4937 4936 4936 4936 4935 4935 4935 4935 4935 4935 4935 4935 4935 4935 4935 4935 4936 4936 4937 4937 4938 4939 4940 4941 4943 4944 4946 4948 4950 4952 4954 4956 4958 4960 4962 4963 4964 4966 4966 4967 4967 4966 4966 4964 4963 4961 4959 4957 4955 4953 4950 4948 4945 4943 4940 4938 4936 4934 4932 4930 4929 4927 4926 4924 4923 4922 4921 4921 4920 4920 4919 4919 4918 4918 4918 4917 4917 4917 4917 4917 4917 4917 4917 4917 4917 4917 4917 4917 4917 4917 4916 4916 4916 4916 4916 4916 4916 4916 4916 4916 4916 4916 4916 4916 4916 4916 4916 4916 4916 4916 4916 4916 4916 4916 4916 4916 4916 4916 4916 4916 4916 4916 4916 4916 4917 4917 4917 4917 4917 4917 4917 4918 4918 4918 4918 4918 4919 4919 4919 4919 4920 4920 4920 4920 4921 4921 4921 4922 4922 4922 4923 4923 4923 4924 4924 4925 4925 4925 4926 4926 4927 4927 4928 4929 4929 4930 4931 4931 4932 4933 4934 4934 4935 4936 4937 4938 4939 4941 4942 4943 4944 4946 4947 4949 4951 4953 4955 4957 4959 4962 4965 4967 4970 4974 4977 4981 4985 4989 4993 4998 5003 5008 5013 5019 5025 5032 5039 5046 5053 5061 5069 5078 5087 5096 5105 5115 5126 5136 5147 5159 5170 5182 5194 5207 5219 5232 5245 5258 5271 5284 5296 5309 5322 5334 5346 5358 5369 5379 5389 5399 5407 5415 5422 5428 5432 5436 5439 5441 5443 5443 5443 5442 5439 5437 5433 5429 5424 5418 5412 5406 5399 5392 5384 5376 5368 5359 5351 5342 5333 5324 5315 5306 5297 5289 5280 5272 5264 5257 5249 5242 5235 5229 5223 5217 5211 5206 5201 5197 5192 5188 5185 5181 5178 5175 5173 5171 5170 5168 5167 5167 5167 5167 5167 5168 5169 5171 5173 5175 5177 5179 5181 5184 5187 5189 5192 5194 5196 5198 5200 5202 5203 5204 5204 5204 5204 5203 5202 5200 5198 5196 5193 5190 5187 5183 5179 5175 5170 5165 5160 5155 5149 5144 5138 5132 5126 5120 5114 5108 5102 5096 5089 5083 5077 5071 5065 5059 5053 5048 5042 5037 5031 5026 5021 5016 5011 5006 5001 4997 4992 4988 4984 4980 4976 4972 4968 4965 4962 4958 4955 4952 4949 4947 4944 4941 4939 4937 4934 4932 4930 4928 4926 4925 4923 4921 4920 4918 4917 4915 4914 4913 4911 4910 4909 4908 4907 4906 4905 4904 4903 4902 4902 4901 4900 4899 4899 4898 4897 4897 4896 4895 4895 4894 4894 4893 4893 4892 4892 4891 4891 4890 4890 4889 4889 4888 4888 4887 4887 4887 4886 4886 4885 4885 4885 4884 4884 4884 4883 4883 4883 4882 4882 4882 4881 4881 4881 4881 4880 4880 4880 4880 4879 4879 4879 4879 4879 4878 4878 4878 4878 4878 4878 4878 4878 4878 4878 4878 4878 4878 4878 4878 4878 4878 4878 4879 4879 4879 4879 4880 4880 4880 4881 4881 4882 4882 4883 4883 4884 4884 4885 4886 4886 4887 4888 4889 4889 4890 4891 4892 4893 4894 4895 4896 4897 4898 4899 4900 4901 4902 4903 4904 4905 4905 4906 4907 4908 4908 4909 4909 4909 4910 4910 4910 4910 4910 4910 4910 4909 4909 4909 4908 4907 4907 4906 4905 4905 4904 4903 4902 4901 4900 4899 4898 4897 4896 4895 4893 4892 4891 4890 4889 4888 4887 4886 4885 4884 4883 4882 4881 4880 4879 4879 4878 4877 4877 4876 4875 4875 4874 4874 4874 4874 4873 4873 4873 4873 4873 4874 4874 4874 4875 4875 4876 4877 4878 4879 4880 4882 4883 4885 4886 4888 4890 4892 4895 4897 4899 4902 4905 4907 4910 4913 4915 4918 4921 4924 4926 4929 4932 4935 4937 4940 4942 4945 4948 4950 4953 4955 4958 4961 4963 4966 4968 4971 4973 4976 4978 4981 4983 4985 4988 4990 4992 4994 4995 4997 4999 5000 5002 5003 5005 5006 5007 5008 5009 5010 5011 5012 5013 5013 5014 5014 5015 5015 5015 5015 5015 5015 5015 5015 5015 5014 5014 5013 5012 5011 5010 5008 5007 5005 5003 5001 4999 4996 4994 4991 4988 4985 4982 4979 4975 4972 4968 4965 4961 4958 4954 4950 4946 4943 4939 4935 4931 4927 4924 4920 4916 4912 4909 4905 4902 4898 4895 4892 4888 4885 4882 4879 4876 4873 4870 4867 4864 4862 4859 4856 4854 4851 4849 4847 4845 4842 4840 4838 4836 4834 4833 4831 4829 4827 4826 4824 4823 4821 4820 4818 4817 4816 4815 4813 4812 4811 4810 4809 4808 4807 4806 4805 4804 4804 4803 4802 4801 4801 4800 4799 4799 4798 4798 4797 4797 4796 4796 4795 4795 4794 4794 4794 4794 4793 4793 4793 4793 4792 4792 4792 4791 4791 4791 4790 4790 4790 4789 4789 4788 4788 4787 4787 4786 4785 4785 4784 4784 4783 4783 4782 4782 4781 4781 4780 4780 4780 4779 4779 4779 4778 4778 4778 4777 4777 4777 4777 4777 4777 4777 4777 4777 4777 4777 4777 4777 4777 4777 4777 4777 4777 4778 4778 4778 4778 4778 4779 4779 4779 4779 4779 4779 4779 4779 4779 4779 4779 4779 4779 4779 4778 4778 4778 4778 4778 4778 4777 4777 4777 4777 4777 4776 4776 4776 4776 4775 4775 4775 4774 4774 4774 4773 4773 4773 4772 4772 4771 4771 4770 4770 4769 4769 4768 4768 4767 4767 4766 4766 4765 4765 4764 4764 4763 4763 4762 4762 4761 4760 4760 4759 4759 4758 4758 4758 4757 4757 4756 4756 4755 4755 4754 4754 4754 4753 4753 4753 4752 4752 4752 4752 4752 4751 4751 4751 4751 4751 4752 4752 4752 4752 4753 4753 4753 4754 4755 4755 4756 4757 4757 4758 4759 4759 4760 4761 4761 4761 4762 4762 4762 4762 4762 4761 4761 4760 4759 4759 4758 4757 4756 4755 4754 4753 4752 4751 4750 4749 4748 4747 4746 4745 4744 4744 4743 4743 4742 4742 4742 4741 4741 4741 4741 4741 4741 4741 4741 4742 4742 4742 4743 4743 4743 4743 4744 4744 4744 4744 4744 4744 4744 4743 4743 4743 4742 4742 4742 4741 4741 4740 4740 4739 4739 4738 4738 4737 4737 4736 4736 4735 4735 4735 4734 4734 4734 4733 4733 4733 4733 4733 4732 4732 4732 4732 4732 4732 4732 4732 4732 4732 4732 4731 4731 4731 4731 4731 4731 4731 4731 4731 4731 4731 4731 4731 4731 4732 4732 4732 4732 4732 4732 4732 4732 4732 4732 4732 4732 4732 4732 4732 4732 4733 4733 4733 4733 4733 4733 4733 4733 4733 4734 4734 4734 4734 4734 4734 4735 4735 4735 4735 4735 4736 4736 4736 4736 4737 4737 4737 4737 4738 4738 4738 4739 4739 4739 4740 4740 4741 4741 4742 4742 4743 4743 4744 4744 4745 4745 4746 4747 4747 4748 4749 4750 4751 4751 4752 4753 4754 4755 4756 4757 4758 4760 4761 4762 4763 4765 4766 4767 4769 4770 4772 4773 4775 4776 4778 4780 4781 4783 4785 4787 4788 4790 4792 4794 4796 4798 4800 4802 4804 4806 4808 4810 4812 4814 4815 4817 4819 4821 4823 4824 4826 4827 4829 4830 4832 4833 4834 4835 4836 4837 4838 4838 4839 4839 4840</intensities>
			</dataPoints>
			<nonAmbientPoints type="Temperature" unit="K">
				<measurementTimes unit="seconds" deltaTime="1">0</measurementTimes>
				<nonAmbientValues>298.150</nonAmbientValues>
			</nonAmbientPoints>
		</scan>
	</xrdMeasurement>
</xrdMeasurements>